<?xml version="1.0" ?>
<robot name="dashgobot" xmlns:xacro="http://ros.org/wiki/xacro">
  <xacro:include filename="$(find dashgo_description)/urdf/dashgobase/common_properties.xacro"/>
  <xacro:include filename="$(find dashgo_description)/urdf/dashgobase/dashgo.gazebo.xacro"/>

  <link name="base_footprint"/>

  <joint name="base_joint" type="fixed">
    <parent link="base_footprint"/>
    <child link="base_link"/>
    <origin xyz="0.0 0.0 0" rpy="0 0 1.57"/>
  </joint>

  <link name="base_link">
    <visual>
      <origin xyz="0 0 0.04" rpy="0 0 0"/>
      <geometry>
        <mesh filename="package://dashgo_description/urdf/dashgobase/meshes/bases/base_link.STL"/>
      </geometry>
      <material name="white"/>
    </visual>

    <collision>
      <origin
        xyz="0 0 0"
        rpy="0 0 0" />
      <geometry>
        <mesh
          filename="package://dashgo_description/urdf/dashgobase/meshes/bases/base_link.STL" />
      </geometry>
    </collision>

    <inertial>
      <origin
        xyz="-5.3591E-07 -4.6799E-09 0.097992"
        rpy="0 0 0" />
      <mass
        value="22.293" />
      <inertia
        ixx="0.31906"
        ixy="7.5186E-09"
        ixz="1.6457E-06"
        iyy="0.3349"
        iyz="4.7391E-09"
        izz="0.45765" />
    </inertial>
  </link>

<!--   <joint name="robot_joint" type="fixed">
    <parent link="base_link"/>
    <child link="robot_link"/>
    <origin xyz="0.0 0.0 0.041" rpy="0 0 0"/>
  </joint>

 <link name="robot_link">
    <visual>
      <origin xyz="0 0 0.0" rpy="0 0 0"/>
      <geometry>
        <mesh filename="package://dashgo_description/urdf/dashgobase/meshes/bases/robot_link.STL"/>
      </geometry>
      <material name="white"/>
    </visual>

    <inertial>
      <origin
        xyz="-0.008188 -8.839E-07 0.27619"
        rpy="0 0 0" />
      <mass
        value="4.3162" />
      <inertia
        ixx="0.047961"
        ixy="8.0458E-08"
        ixz="0.001459"
        iyy="0.04767"
        iyz="2.9481E-07"
        izz="0.046024" />
    </inertial>

    <collision>
      <origin
        xyz="0 0 0"
        rpy="0 0 0" />
      <geometry>
        <mesh filename="package://dashgo_description/urdf/dashgobase/meshes/bases/robot_link.STL"/>
      </geometry>
    </collision>

  </link> -->

  <joint name="wheel_left_joint" type="continuous">
    <parent link="base_link"/>
    <child link="wheel_left_link"/>
    <origin xyz="0.0 0.185 0.06" rpy="-1.57 0 0"/>
    <axis xyz="0 0 1"/>
  </joint>

  <link name="wheel_left_link">
    <visual>
      <origin xyz="-0.06 -0.06 0.015" rpy="-1.57 0 0"/>
      <geometry>
        <mesh filename="package://dashgo_description/urdf/dashgobase/meshes/wheels/banh_xe.STL" scale="0.001 0.001 0.001"/>
      </geometry>
      <material name="dark"/>
    </visual>

    <collision>
      <origin xyz="0 0 0" rpy="0 0 0"/>
      <geometry>
        <cylinder length="0.036" radius="0.066"/>
      </geometry>
    </collision>

    <inertial>
      <origin xyz="0 0 0" />
      <mass value="2.8498940e-02" />
      <inertia ixx="1.1175580e-05" ixy="-4.2369783e-11" ixz="-5.9381719e-09"
               iyy="1.1192413e-05" iyz="-1.4400107e-11"
               izz="2.0712558e-05" />
      </inertial>
  </link>

  <joint name="wheel_right_joint" type="continuous">
    <parent link="base_link"/>
    <child link="wheel_right_link"/>
    <origin xyz="0.0 -0.185 0.06" rpy="-1.57 0 0"/>
    <axis xyz="0 0 1"/>
  </joint>

  <link name="wheel_right_link">
    <visual>
      <origin xyz="-0.06 0.06 -0.015" rpy="1.57 0 0"/>
      <geometry>
        <mesh filename="package://dashgo_description/urdf/dashgobase/meshes/wheels/banh_xe.STL" scale="0.001 0.001 0.001"/>
      </geometry>
      <material name="dark"/>
    </visual>

    <collision>
      <origin xyz="0 0 0" rpy="0 0 0"/>
      <geometry>
        <cylinder length="0.036" radius="0.066"/>
      </geometry>
    </collision>

    <inertial>
      <origin xyz="0 0 0" />
      <mass value="2.8498940e-02" />
      <inertia ixx="1.1175580e-05" ixy="-4.2369783e-11" ixz="-5.9381719e-09"
               iyy="1.1192413e-05" iyz="-1.4400107e-11"
               izz="2.0712558e-05" />
      </inertial>
  </link>

  <joint name="caster_back_joint" type="fixed">
    <parent link="base_link"/>
    <child link="caster_back_link"/>
    <origin xyz="-0.162 0.0 0.025" rpy="-1.57 0 0"/>
  </joint>

  <link name="caster_back_link">
    <visual>
      <origin xyz="0 0 0" rpy="0 0 0"/>
      <geometry>
        <cylinder length="0.02" radius="0.02"/>
      </geometry>
      <material name="orange"/>
    </visual>
    <collision>
        <origin xyz="0 0 0" rpy="0 0 0"/>
        <geometry>
          <cylinder length="0.02" radius="0.02"/>
        </geometry>
    </collision>
    <inertial>
      <origin xyz="0 0 0" />
      <mass value="0.005" />
      <inertia ixx="0.001" ixy="0.0" ixz="0.0"
               iyy="0.001" iyz="0.0"
               izz="0.001" />
    </inertial>
  </link>

  <joint name="caster_front_joint" type="fixed">
    <parent link="base_link"/>
    <child link="caster_front_link"/>
    <origin xyz="0.162 0.0 0.025" rpy="-1.57 0 0"/>
  </joint>

  <link name="caster_front_link">
    <visual>
      <origin xyz="0 0 0" rpy="0 0 0"/>
      <geometry>
        <cylinder length="0.02" radius="0.02"/>
      </geometry>
      <material name="orange"/>
    </visual>

    <collision>
        <origin xyz="0 0 0" rpy="0 0 0"/>
        <geometry>
          <cylinder length="0.02" radius="0.02"/>
        </geometry>
    </collision>

    <inertial>
      <origin xyz="0 0 0" />
      <mass value="0.005" />
      <inertia ixx="0.001" ixy="0.0" ixz="0.0"
               iyy="0.001" iyz="0.0"
               izz="0.001" />
    </inertial>
  </link>

  <joint name="imu_joint" type="fixed">
    <parent link="base_link"/>
    <child link="imu_link"/>
    <origin xyz="0.0 0 0.80" rpy="0 0 0"/>
  </joint>

  <link name="imu_link"/>

<link name="laser_frame_01">
    <visual>
      <origin xyz="0 0 0.0" rpy="0 0 0"/>
      <geometry>
        <mesh filename="package://dashgo_description/urdf/dashgobase/meshes/sensors/laser_frame.STL"/>
      </geometry>
      <material name="dark"/>
    </visual>

    <collision>
      <origin xyz="0 0 0" rpy="0 0 0"/>
      <geometry>
        <cylinder length="0.063" radius="0.055"/>
      </geometry>
    </collision>

    <inertial>
      <mass value="0.114" />
      <origin xyz="0 0 0" />
      <inertia ixx="0.001" ixy="0.0" ixz="0.0"
               iyy="0.001" iyz="0.0"
               izz="0.001" />
    </inertial>
  </link>
  
  <joint name="joint_sensor_laser_1" type="fixed">
    <origin xyz="0 0.0 0.317" rpy="0.0 0.0 0.0"/>
    <parent link="base_link"/>
    <child link="laser_frame_01"/>
  </joint>

  <link name="laser_frame_02">
    <visual>
      <origin xyz="0 0 0.0" rpy="0 0 0"/>
      <geometry>
        <mesh filename="package://dashgo_description/urdf/dashgobase/meshes/sensors/laser_frame.STL"/>
      </geometry>
      <material name="dark"/>
    </visual>

    <collision>
      <origin xyz="0 0 0" rpy="0 0 0"/>
      <geometry>
        <cylinder length="0.063" radius="0.055"/>
      </geometry>
    </collision>

    <inertial>
      <mass value="0.114" />
      <origin xyz="0 0 0" />
      <inertia ixx="0.001" ixy="0.0" ixz="0.0"
               iyy="0.001" iyz="0.0"
               izz="0.001" />
    </inertial>
  </link>

    <joint name="base_link__collum_1" type="fixed">
        <origin xyz="0.06 -0.05 0.35" rpy="0.0 0.0 0.0"/>
        <parent link="base_link"/>
        <child link="collum_1"/>
    </joint>

    <link name="collum_1">
        <visual>
            <origin xyz="0.0 0.0 0" rpy="0.0 0.0 0.0"/>
                <geometry>
                    <cylinder radius="0.005" length="0.1"/>
                </geometry>
                <material name = "dark"/>
        </visual>

        <collision>
            <origin xyz="0.0 0.0 0.0" rpy="0.0 0.0 0.0"/>
                <geometry>
                    <cylinder radius="0.005" length="0.1"/>
                </geometry>
        </collision>
        <inertial>
            <origin xyz="0.0 0.0 0.0" rpy="0.0 0.0 0.0"/>
            <mass value="0.01"/>
            <inertia ixx="0.001" ixy="0.0" ixz="0.0" iyy="0.001" iyz="0.0" izz="0.001"/>
        </inertial>
    </link>
    <joint name="base_link__collum_2" type="fixed">
        <origin xyz="-0.06 -0.05 0.35" rpy="0.0 0.0 0.0"/>
        <parent link="base_link"/>
        <child link="collum_2"/>
    </joint>

    <link name="collum_2">
        <visual>
            <origin xyz="0.0 0.0 0" rpy="0.0 0.0 0.0"/>
                <geometry>
                    <cylinder radius="0.005" length="0.1"/>
                </geometry>
                <material name = "dark"/>
        </visual>

        <collision>
            <origin xyz="0.0 0.0 0.0" rpy="0.0 0.0 0.0"/>
                <geometry>
                    <cylinder radius="0.005" length="0.1"/>
                </geometry>
        </collision>
        <inertial>
            <origin xyz="0.0 0.0 0.0" rpy="0.0 0.0 0.0"/>
            <mass value="0.01"/>
            <inertia ixx="0.001" ixy="0.0" ixz="0.0" iyy="0.001" iyz="0.0" izz="0.001"/>
        </inertial>
    </link>
    <joint name="base_link__collum_3" type="fixed">
        <origin xyz="0 0.06 0.35" rpy="0.0 0.0 0.0"/>
        <parent link="base_link"/>
        <child link="collum_3"/>
    </joint>

    <link name="collum_3">
        <visual>
            <origin xyz="0.0 0.0 0" rpy="0.0 0.0 0.0"/>
                <geometry>
                    <cylinder radius="0.005" length="0.1"/>
                </geometry>
                <material name = "dark"/>
        </visual>

        <collision>
            <origin xyz="0.0 0.0 0.0" rpy="0.0 0.0 0.0"/>
                <geometry>
                    <cylinder radius="0.005" length="0.1"/>
                </geometry>
        </collision>
        <inertial>
            <origin xyz="0.0 0.0 0.0" rpy="0.0 0.0 0.0"/>
            <mass value="0.01"/>
            <inertia ixx="0.001" ixy="0.0" ixz="0.0" iyy="0.001" iyz="0.0" izz="0.001"/>
        </inertial>
    </link>

    <joint name="base_link__plate_1" type="fixed">
        <parent link="base_link"/>
        <child link="plate_1"/>
        <origin xyz="0.0 0.0 0.4" rpy="0.0 0.0 0.0"/>
    </joint>
    

    <link name="plate_1">
        <visual>
            <origin xyz="0.0 0.0 0.0" rpy="0.0 0.0 0.0"/>
            <geometry>
                <cylinder radius="0.1" length="0.002"/>
            </geometry>
        </visual>

        <collision>
            <origin xyz="0.0 0.0 0.0" rpy="0.0 0.0 0.0"/>
            <geometry>
                <cylinder radius="0.2" length="0.025"/>
            </geometry>
        </collision>
        <inertial>
            <origin xyz="0.0 0.0 0.0" rpy="0.0 0.0 0.0"/>
            <mass value="0.05"/>
            <inertia ixx="0.005" ixy="0.0" ixz="0.0" iyy="0.005" iyz="0.0" izz="0.005"/>
        </inertial>
        
    </link>
  
  <joint name="joint_sensor_laser_2" type="fixed">
    <origin xyz="0 0.0 0.43" rpy="0.0 0.0 0.0"/>
    <parent link="base_link"/>
    <child link="laser_frame_02"/>
  </joint>

  <joint name="sonar_joint" type="fixed">
    <origin xyz="0.2 0 0.125" rpy="0 0 0"/>
    <parent link="base_link" />
    <child link="sonar_link" />
</joint>

<link name="sonar_link" />

<!-- this is only a hack until gazebo fixes their SonarSensor which points towards -z per default (incompatible with rviz which points towards x) -->

<joint name="sonar1_joint_fake" type="fixed">
    <origin rpy="0 ${-pi/2} 0"/>
    <parent link="sonar_link" />
    <child link="sonar_link_fake" />
</joint>

<link name="sonar_link_fake"/>
</robot>